Workbook

Sheet 1. 만족도
B1: 2026년 양촌읍 가까이배움터 정규강좌 1기 만족도 조사
B2: ○ 응답률 및 주요지표
B3: 연번 | C3: 구분 | D3: 과 목 | E3: 수강인원 | F3: 응답인원 | G3: 응답률 | H3: 만족도 평균 | I3: 강사 적극성 | J3: 강사 전문성 | K3: 내용 충실성 | L3: 시간대 적정성 | M3: 수업 활용 | N3: 수업 유익성 | O3: 교재 및 자료 충분성 | P3: 강의시설 만족도 | Q3: 체감 만족도
D4: 계 | E4: =SUM(E5:E20) -> 266 | F4: =SUM(F5:F20) -> 201 | G4: =AVERAGE(G5:G20) -> 0.77791773 | H4: =AVERAGE(H5:H20) -> #DIV/0! | I4: =AVERAGE(I5:I20) -> 4.7564286 | J4: =AVERAGE(J5:J20) -> 4.6964286 | K4: =AVERAGE(K5:K20) -> 4.6928571 | L4: =AVERAGE(L5:L20) -> 4.3807143 | M4: =AVERAGE(M5:M20) -> 4.5407143 | N4: =AVERAGE(N5:N20) -> 4.66 | ... Q4: =AVERAGE(Q5:Q20) -> 4.5364286
B5: 1 | C5: 직업능력 | D5: 컴퓨터활용능력 2급 실기 자격증(온라인) | E5: 12 | F5: 5 | G5: =F5/E5 -> 0.41666667 | H5: =AVERAGE(I5:Q5) -> 4.4788889 | I5: 4.77 | J5: 4.85 | K5: 4.77 | L5: 3.77 | M5: 4.46 | N5: 4.62 | O5: 4.54 | P5: 4.15 | Q5: 4.38
B6: 2 | D6: 정리수납 전문가 자격과정 | E6: 6 | F6: 6 | G6: =F6/E6 -> 1 | H6: =AVERAGE(I6:Q6) -> 4.7222222 | I6: 5 | J6: 4.83 | K6: 4.67 | L6: 4.5 | M6: 4.67 | N6: 4.67 | O6: 4.83 | P6: 4.5 | Q6: 4.83
B7: 3 | C7: 인문교양 | D7: 한글&엑셀 기초실무 | E7: 12 | F7: 12 | G7: =F7/E7 -> 1 | H7: =AVERAGE(I7:Q7) -> 4.4966667 | I7: 4.64 | J7: 4.64 | K7: 4.55 | L7: 4.27 | M7: 4.55 | N7: 4.64 | O7: 4.64 | P7: 4.09 | Q7: 4.45
B8: 4 | D8: 영어회화(초급) | E8: 15 | F8: 15 | G8: =F8/E8 -> 1 | H8: =AVERAGE(I8:Q8) -> 4.2644444 | I8: 4.38 | J8: 4.54 | K8: 4.38 | L8: 4.23 | M8: 4 | N8: 4.31 | O8: 4.08 | P8: 4.08 | Q8: 4.38
B9: 5 | D9: 어르신이 행복한 웃음치료 | E9: 15 | F9: 10 | G9: =F9/E9 -> 0.66666667 | H9: =AVERAGE(I9:Q9) -> 4.9911111 | I9: 5 | J9: 5 | K9: 5 | L9: 5 | M9: 5 | N9: 5 | O9: 5 | P9: 5 | Q9: 4.92
B10: 6 | C10: 문화예술 | D10: 힐링 노래교실 | E10: 39 | F10: 22 | G10: =F10/E10 -> 0.56410256 | H10: =AVERAGE(I10:Q10) -> 4.77 | I10: 5 | J10: 4.87 | K10: 4.93 | L10: 4 | M10: 4.8 | N10: 5 | O10: 4.93 | P10: 4.53 | Q10: 4.87
B11: 7 | D11: 한문서예 | E11: 12 | F11: 9 | G11: =F11/E11 -> 0.75 | H11: =AVERAGE(I11:Q11) -> 4.4933333 | I11: 4.76 | J11: 4.6 | K11: 4.64 | L11: 4.44 | M11: 4.4 | N11: 4.48 | O11: 4.44 | P11: 4.28 | Q11: 4.4
B12: 8 | D12: 치매예방 미술 프로그램(연필스케치) | E12: 15 | F12: 12 | G12: =F12/E12 -> 0.8 | H12: =AVERAGE(I12:Q12) -> 4.6655556 | I12: 4.83 | J12: 4.83 | K12: 4.89 | L12: 4.61 | M12: 4.72 | N12: 4.72 | O12: 4.5 | P12: 4.5 | Q12: 4.39
B13: 9 | D13: 우쿨렐레 | E13: 16 | F13: 12 | G13: =F13/E13 -> 0.75 | H13: =AVERAGE(I13:Q13) -> 4.5466667 | I13: 4.82 | J13: 4.82 | K13: 4.73 | L13: 4.09 | M13: 4.64 | N13: 4.64 | O13: 4.55 | P13: 4.27 | Q13: 4.36
B14: 10 | D14: 댄스스포츠(중급) | E14: 25 | F14: 21 | G14: =F14/E14 -> 0.84 | H14: =AVERAGE(I14:Q14) -> 4.7822222 | I14: 4.89 | J14: 4.84 | K14: 4.84 | L14: 4.63 | M14: 4.63 | N14: 4.84 | O14: 4.74 | P14: 4.79 | Q14: 4.84
B15: 11 | D15: 밸리댄스 | E15: 18 | F15: 12 | G15: =F15/E15 -> 0.66666667 | H15: =AVERAGE(I15:Q15) -> 4.4222222 | I15: 4.6 | J15: 4.53 | K15: 4.67 | L15: 4.27 | M15: 4.2 | N15: 4.6 | O15: 4.33 | P15: 4.33 | Q15: 4.27
B16: 12 | D16: 시니어건강 라인댄스 | E16: 23 | F16: 20 | G16: =F16/E16 -> 0.86956522 | H16: =AVERAGE(I16:Q16) -> #DIV/0!
B17: 13 | D17: 시니어 건강체조 | E17: 18 | F17: 14 | G17: =F17/E17 -> 0.77777778 | H17: =AVERAGE(I17:Q17) -> #DIV/0!
B18: 14 | C18: 기초문해 | D18: 한글교실(어르신) | E18: 12 | F18: 11 | G18: =F18/E18 -> 0.91666667 | H18: =AVERAGE(I18:Q18) -> 3.7222222 | I18: 3.9 | J18: 3.4 | K18: 3.7 | L18: 3.8 | M18: 3.8 | N18: 3.8 | O18: 3.5 | P18: 3.8 | Q18: 3.8
B19: 15 | D19: 컴퓨터&스마트폰 기초(키오스크활용) | E19: 14 | F19: 8 | G19: =F19/E19 -> 0.57142857 | H19: =AVERAGE(I19:Q19) -> 4.8722222 | I19: 5 | J19: 5 | K19: 5 | L19: 4.85 | M19: 4.77 | N19: 4.92 | O19: 4.85 | P19: 4.77 | Q19: 4.69
B20: 16 | D20: 영어교실(어르신) | E20: 14 | F20: 12 | G20: =F20/E20 -> 0.85714286 | H20: =AVERAGE(I20:Q20) -> 4.8144444 | I20: 5 | J20: 5 | K20: 4.93 | L20: 4.87 | M20: 4.93 | N20: 5 | O20: 4.6 | P20: 4.07 | Q20: 4.93

Sheet 응답자 특성
B1: 응답자 특성
B3: 연번 | C3: 교육과목 | D3: 성별 | G3: 거주지역 | X3: 연령 | AE3: 직업
D4: 남 | E4: 여 | F4: 계 | G4: 통진읍 | H4: 고촌읍 | I4: 양촌읍 | J4: 월곶면 | K4: 하성면 | L4: 대곶면 | M4: 김포본동 | N4: 장기본동 | O4: 사우동 | P4: 풍무동 | Q4: 장기동 | R4: 구래동 | S4: 마산동 | T4: 운양동 | U4: 기타지역 | V4: 계 | W4: 만19세이하 | X4: 20대 | Y4: 30대 | Z4: 40대 | AA4: 50대 | AB4: 60대 | AC4: 70대이상 | AD4: 계 | AE4: 직장인 | AF4: 자영업 | AG4: 농어업 축산임업 | AH4: 주부 | AI4: 학생 | AJ4: 기타 | AK4: 계
C5: 계 | D5: =SUM(D6:D20) -> 28 | E5: =SUM(E6:E20) -> 187 | F5: =SUM(F6:F20) -> 215 | G5: =SUM(G6:G20) -> 4 | H5: =SUM(H6:H20) -> 2 | I5: =SUM(I6:I20) -> 133 | J5: =SUM(J6:J20) -> 1 | K5: =SUM(K6:K20) -> 3 | ... V5: =SUM(V6:V20) -> 215 | X5: =SUM(X6:X20) -> 1 | Y5: =SUM(Y6:Y20) -> 1 | Z5: =SUM(Z6:Z20) -> 13 | AA5: =SUM(AA6:AA20) -> 36 | AB5: =SUM(AB6:AB20) -> 66 | AC5: =SUM(AC6:AC20) -> 98 | AD5: =SUM(AD6:AD20) -> 215 | AE5: =SUM(AE6:AE20) -> 18 | ... AK5: =SUM(AK6:AK20) -> 215
B6: 1 | C6: 컴퓨터활용능력 2급 실기 자격증(온라인) | D6: 3 | E6: 10 | F6: =SUM(D6:E6) -> 13 | G6: 1 | I6: 2 | M6: 3 | Q6: 2 | R6: 2 | S6: 3 | V6: =SUM(G6:U6) -> 13 | X6: 1 | Z6: 3 | AA6: 5 | AB6: 2 | AC6: 2 | AD6: =SUM(X6:AC6) -> 13 | AE6: 2 | AF6: 3 | AH6: 8 | AK6: =SUM(AE6:AJ6) -> 13
B7: 2 | C7: 정리수납 전문가 자격과정 | D7: 0 | E7: 6 | F7: =SUM(D7:E7) -> 6 | I7: 3 | R7: 2 | T7: 1 | V7: =SUM(G7:U7) -> 6 | Z7: 1 | AA7: 3 | AC7: 2 | AD7: =SUM(X7:AC7) -> 6 | AE7: 1 | AF7: 1 | AH7: 4 | AK7: =SUM(AE7:AJ7) -> 6
B8: 3 | C8: 한글&엑셀 기초실무 | D8: 4 | E8: 7 | F8: =SUM(D8:E8) -> 11 | G8: 1 | H8: 1 | I8: 6 | N8: 1 | Q8: 1 | R8: 1 | V8: =SUM(G8:U8) -> 11 | AA8: 4 | AB8: 3 | AC8: 4 | AD8: =SUM(X8:AC8) -> 11 | AE8: 1 | AF8: 1 | AH8: 7 | AJ8: 2 | AK8: =SUM(AE8:AJ8) -> 11
B9: 4 | C9: 영어회화(초급) | D9: 0 | E9: 13 | F9: =SUM(D9:E9) -> 13 | I9: 4 | L9: 1 | N9: 1 | R9: 3 | S9: 3 | T9: 1 | V9: =SUM(G9:U9) -> 13 | Z9: 3 | AA9: 3 | AB9: 4 | AC9: 3 | AD9: =SUM(X9:AC9) -> 13 | AE9: 3 | AH9: 10 | AK9: =SUM(AE9:AJ9) -> 13
B10: 5 | C10: 어르신이 행복한 웃음치료 | D10: 1 | E10: 12 | F10: =SUM(D10:E10) -> 13 | I10: 12 | R10: 1 | V10: =SUM(G10:U10) -> 13 | AB10: 1 | AC10: 12 | AD10: =SUM(X10:AC10) -> 13 | AH10: 12 | AJ10: 1 | AK10: =SUM(AE10:AJ10) -> 13
B11: 6 | C11: 힐링 노래교실 | D11: 1 | E11: 14 | F11: =SUM(D11:E11) -> 15 | G11: 1 | H11: 1 | I11: 10 | K11: 2 | R11: 1 | V11: =SUM(G11:U11) -> 15 | AA11: 6 | AB11: 4 | AC11: 5 | AD11: =SUM(X11:AC11) -> 15 | AE11: 3 | AF11: 1 | AG11: 1 | AH11: 10 | AK11: =SUM(AE11:AJ11) -> 15
B12: 7 | C12: 한문서예 | D12: 6 | E12: 19 | F12: =SUM(D12:E12) -> 25 | I12: 17 | M12: 2 | R12: 3 | S12: 3 | V12: =SUM(G12:U12) -> 25 | AA12: 2 | AB12: 8 | AC12: 15 | AD12: =SUM(X12:AC12) -> 25 | AE12: 2 | AH12: 18 | AJ12: 5 | AK12: =SUM(AE12:AJ12) -> 25
B13: 8 | C13: 치매예방 미술 프로그램(연필스케치) | D13: 0 | E13: 18 | F13: =SUM(D13:E13) -> 18 | I13: 13 | R13: 3 | T13: 2 | V13: =SUM(G13:U13) -> 18 | AA13: 2 | AB13: 7 | AC13: 9 | AD13: =SUM(X13:AC13) -> 18 | AH13: 18 | AK13: =SUM(AE13:AJ13) -> 18
B14: 9 | C14: 우쿨렐레 | D14: 0 | E14: 11 | F14: =SUM(D14:E14) -> 11 | I14: 3 | N14: 1 | Q14: 2 | R14: 2 | S14: 3 | V14: =SUM(G14:U14) -> 11 | Y14: 1 | AA14: 3 | AB14: 4 | AC14: 3 | AD14: =SUM(X14:AC14) -> 11 | AE14: 2 | AH14: 8 | AJ14: 1 | AK14: =SUM(AE14:AJ14) -> 11
B15: 10 | C15: 댄스스포츠(중급) | D15: 0 | E15: 19 | F15: =SUM(D15:E15) -> 19 | I15: 14 | R15: 3 | S15: 2 | V15: =SUM(G15:U15) -> 19 | Z15: 5 | AA15: 3 | AB15: 7 | AC15: 4 | AD15: =SUM(X15:AC15) -> 19 | AE15: 2 | AH15: 17 | AK15: =SUM(AE15:AJ15) -> 19
B16: 11 | C16: 밸리댄스 | D16: 5 | E16: 10 | F16: =SUM(D16:E16) -> 15 | G16: 1 | I16: 9 | K16: 1 | N16: 1 | P16: 1 | Q16: 1 | R16: 1 | V16: =SUM(G16:U16) -> 15 | Z16: 1 | AA16: 3 | AB16: 5 | AC16: 6 | AD16: =SUM(X16:AC16) -> 15 | AE16: 1 | AF16: 3 | AG16: 2 | AH16: 9 | AK16: =SUM(AE16:AJ16) -> 15
B17: 12 | C17: 시니어건강 라인댄스 | D17: 0 | E17: 18 | F17: =SUM(D17:E17) -> 18 | I17: 12 | J17: 1 | N17: 1 | Q17: 1 | R17: 2 | S17: 1 | V17: =SUM(G17:U17) -> 18 | AA17: 2 | AB17: 9 | AC17: 7 | AD17: =SUM(X17:AC17) -> 18 | AF17: 1 | AH17: 17 | AK17: =SUM(AE17:AJ17) -> 18
B18: 13 | C18: 시니어 건강체조 | D18: 0 | E18: 10 | F18: =SUM(D18:E18) -> 10 | I18: 10 | V18: =SUM(G18:U18) -> 10 | AB18: 1 | AC18: 9 | AD18: =SUM(X18:AC18) -> 10 | AG18: 1 | AH18: 9 | AK18: =SUM(AE18:AJ18) -> 10
B19: 14 | C19: 한글교실(어르신) | D19: 2 | E19: 11 | F19: =SUM(D19:E19) -> 13 | I19: 7 | P19: 1 | R19: 2 | S19: 2 | T19: 1 | V19: =SUM(G19:U19) -> 13 | AB19: 5 | AC19: 8 | AD19: =SUM(X19:AC19) -> 13 | AF19: 1 | AH19: 9 | AI19: 1 | AJ19: 2 | AK19: =SUM(AE19:AJ19) -> 13
B20: 15 | C20: 컴퓨터&스마트폰 기초(키오스크활용) | D20: 6 | E20: 9 | F20: =SUM(D20:E20) -> 15 | I20: 11 | R20: 3 | S20: 1 | V20: =SUM(G20:U20) -> 15 | AB20: 6 | AC20: 9 | AD20: =SUM(X20:AC20) -> 15 | AE20: 1 | AF20: 3 | AG20: 4 | AH20: 6 | AJ20: 1 | AK20: =SUM(AE20:AJ20) -> 15
B21: 16 | C21: 영어교실(어르신) | F21: =SUM(D21:E21) -> 0 | V21: =SUM(G21:U21) -> 0 | AD21: =SUM(X21:AC21) -> 0 | AK21: =SUM(AE21:AJ21) -> 0

Sheet 객관식
B1: 교육에 관한 질문
B3: 연번 | C3: 교육과목 | D3: 강사 적극성 | J3: 강사 전문성 | P3: 내용 충실성 | V3: 시간대 적정성 | AB3: 수업의 활용도 | AH3: 수업 유익성 | AN3: 교재 및 자료 충분성 | AT3: 강의시설 만족도 | AZ3: 체감 만족도
D4: 매우 그렇다. | E4: 그렇다 | F4: 보통 | G4: 그렇지 않다. | H4: 매우 그렇지 않다 | I4: 응답 | J4: 매우 그렇다. | K4: 그렇다 | L4: 보통 | M4: 그렇지 않다. | N4: 매우 그렇지 않다 | O4: 응답 | P4: 매우 그렇다. | Q4: 그렇다 | R4: 보통 | S4: 그렇지 않다. | T4: 매우 그렇지 않다 | U4: 응답 | V4: 매우 그렇다. | W4: 그렇다 | X4: 보통 | Y4: 그렇지 않다. | Z4: 매우 그렇지 않다 | AA4: 응답 | AB4: 매우 그렇다. | AC4: 그렇다 | AD4: 보통 | AE4: 그렇지 않다. | AF4: 매우 그렇지 않다 | AG4: 응답 | AH4: 매우 그렇다. | AI4: 그렇다 | AJ4: 보통 | AK4: 그렇지 않다. | AL4: 매우 그렇지 않다 | AM4: 응답 | AN4: 매우 그렇다. | AO4: 그렇다 | AP4: 보통 | AQ4: 그렇지 않다. | AR4: 매우 그렇지 않다 | AS4: 응답 | AT4: 매우 그렇다. | AU4: 그렇다 | AV4: 보통 | AW4: 그렇지 않다. | AX4: 매우 그렇지 않다 | AY4: 응답 | AZ4: 매우 그렇다. | BA4: 그렇다 | BB4: 보통 | BC4: 그렇지 않다. | BD4: 매우 그렇지 않다 | BE4: 응답
C5: 계 | D5: =SUM(D6:D20) -> 176 | E5: =SUM(E6:E20) -> 32 | F5: =SUM(F6:F20) -> 5 | G5: =SUM(G6:G20) -> 1 | H5: =SUM(H6:H20) -> 1 | I5: =SUM(I6:I20) -> 215 | J5: =SUM(J6:J20) -> 168 | K5: =SUM(K6:K20) -> 38 | ... BE5: =SUM(BE6:BE20) -> 215
B6: 1 | C6: 컴퓨터활용능력 2급 실기 자격증(온라인) | D6: 10 | E6: 3 | I6: =SUM(D6:H6) -> 13 | J6: 11 | K6: 2 | O6: =SUM(J6:N6) -> 13 | P6: 10 | Q6: 3 | U6: =SUM(P6:T6) -> 13 | V6: 4 | W6: 4 | X6: 3 | Y6: 2 | AA6: =SUM(V6:Z6) -> 13 | AB6: 7 | AC6: 5 | AD6: 1 | AG6: =SUM(AB6:AF6) -> 13 | AH6: 9 | AI6: 3 | AJ6: 1 | AM6: =SUM(AH6:AL6) -> 13 | AN6: 9 | AO6: 2 | AP6: 2 | AS6: =SUM(AN6:AR6) -> 13 | AT6: 5 | AU6: 5 | AV6: 3 | AY6: =SUM(AT6:AX6) -> 13 | AZ6: 6 | BA6: 6 | BB6: 1 | BE6: =SUM(AZ6:BD6) -> 13
B7: 2 | C7: 정리수납 전문가 자격과정 | D7: 6 | I7: =SUM(D7:H7) -> 6 | J7: 5 | K7: 1 | O7: =SUM(J7:N7) -> 6 | P7: 4 | Q7: 2 | U7: =SUM(P7:T7) -> 6 | V7: 3 | W7: 3 | AA7: =SUM(V7:Z7) -> 6 | AB7: 4 | AC7: 2 | AG7: =SUM(AB7:AF7) -> 6 | AH7: 4 | AI7: 2 | AM7: =SUM(AH7:AL7) -> 6 | AN7: 5 | AO7: 1 | AS7: =SUM(AN7:AR7) -> 6 | AT7: 3 | AU7: 3 | AY7: =SUM(AT7:AX7) -> 6 | AZ7: 5 | BA7: 1 | BE7: =SUM(AZ7:BD7) -> 6
B8: 3 | C8: 한글&엑셀 기초실무 | D8: 7 | E8: 4 | I8: =SUM(D8:H8) -> 11 | J8: 7 | K8: 4 | O8: =SUM(J8:N8) -> 11 | P8: 6 | Q8: 5 | U8: =SUM(P8:T8) -> 11 | V8: 4 | W8: 6 | X8: 1 | AA8: =SUM(V8:Z8) -> 11 | AB8: 7 | AC8: 3 | AD8: 1 | AG8: =SUM(AB8:AF8) -> 11 | AH8: 7 | AI8: 4 | AM8: =SUM(AH8:AL8) -> 11 | AN8: 7 | AO8: 4 | AS8: =SUM(AN8:AR8) -> 11 | AT8: 6 | AU8: 1 | AV8: 3 | AW8: 1 | AY8: =SUM(AT8:AX8) -> 11 | AZ8: 5 | BA8: 6 | BE8: =SUM(AZ8:BD8) -> 11
B9: 4 | C9: 영어회화(초급) | D9: 6 | E9: 6 | F9: 1 | I9: =SUM(D9:H9) -> 13 | J9: 7 | K9: 6 | O9: =SUM(J9:N9) -> 13 | P9: 6 | Q9: 6 | R9: 1 | U9: =SUM(P9:T9) -> 13 | V9: 5 | W9: 7 | Y9: 1 | AA9: =SUM(V9:Z9) -> 13 | AB9: 4 | AC9: 6 | AD9: 2 | AE9: 1 | AG9: =SUM(AB9:AF9) -> 13 | AH9: 6 | AI9: 5 | AJ9: 2 | AM9: =SUM(AH9:AL9) -> 13 | AN9: 4 | AO9: 6 | AP9: 3 | AS9: =SUM(AN9:AR9) -> 13 | AT9: 4 | AU9: 6 | AV9: 3 | AY9: =SUM(AT9:AX9) -> 13 | AZ9: 6 | BA9: 6 | BB9: 1 | BE9: =SUM(AZ9:BD9) -> 13
B10: 5 | C10: 어르신이 행복한 웃음치료 | D10: 13 | I10: =SUM(D10:H10) -> 13 | J10: 13 | O10: =SUM(J10:N10) -> 13 | P10: 13 | U10: =SUM(P10:T10) -> 13 | V10: 13 | AA10: =SUM(V10:Z10) -> 13 | AB10: 13 | AG10: =SUM(AB10:AF10) -> 13 | AH10: 13 | AM10: =SUM(AH10:AL10) -> 13 | AN10: 13 | AS10: =SUM(AN10:AR10) -> 13 | AT10: 13 | AY10: =SUM(AT10:AX10) -> 13 | AZ10: 12 | BA10: 1 | BE10: =SUM(AZ10:BD10) -> 13
B11: 6 | C11: 힐링 노래교실 | D11: 15 | I11: =SUM(D11:H11) -> 15 | J11: 13 | K11: 2 | O11: =SUM(J11:N11) -> 15 | P11: 14 | Q11: 1 | U11: =SUM(P11:T11) -> 15 | V11: 9 | W11: 2 | X11: 1 | Y11: 1 | Z11: 2 | AA11: =SUM(V11:Z11) -> 15 | AB11: 12 | AC11: 3 | AG11: =SUM(AB11:AF11) -> 15 | AH11: 15 | AM11: =SUM(AH11:AL11) -> 15 | AN11: 14 | AO11: 1 | AS11: =SUM(AN11:AR11) -> 15 | AT11: 10 | AU11: 3 | AV11: 2 | AY11: =SUM(AT11:AX11) -> 15 | AZ11: 13 | BA11: 2 | BE11: =SUM(AZ11:BD11) -> 15
B12: 7 | C12: 한문서예 | D12: 20 | E12: 4 | F12: 1 | I12: =SUM(D12:H12) -> 25 | J12: 17 | K12: 6 | L12: 2 | O12: =SUM(J12:N12) -> 25 | P12: 18 | Q12: 5 | R12: 2 | U12: =SUM(P12:T12) -> 25 | V12: 15 | W12: 7 | X12: 2 | Y12: 1 | AA12: =SUM(V12:Z12) -> 25 | AB12: 14 | AC12: 7 | AD12: 4 | AG12: =SUM(AB12:AF12) -> 25 | AH12: 14 | AI12: 9 | AJ12: 2 | AM12: =SUM(AH12:AL12) -> 25 | AN12: 15 | AO12: 6 | AP12: 4 | AS12: =SUM(AN12:AR12) -> 25 | AT12: 14 | AU12: 4 | AV12: 7 | AY12: =SUM(AT12:AX12) -> 25 | AZ12: 14 | BA12: 7 | BB12: 4 | BE12: =SUM(AZ12:BD12) -> 25
B13: 8 | C13: 치매예방 미술 프로그램(연필스케치) | D13: 15 | E13: 3 | I13: =SUM(D13:H13) -> 18 | J13: 15 | K13: 3 | O13: =SUM(J13:N13) -> 18 | P13: 16 | Q13: 2 | U13: =SUM(P13:T13) -> 18 | V13: 13 | W13: 4 | Y13: 1 | AA13: =SUM(V13:Z13) -> 18 | AB13: 13 | AC13: 5 | AG13: =SUM(AB13:AF13) -> 18 | AH13: 13 | AI13: 5 | AM13: =SUM(AH13:AL13) -> 18 | AN13: 11 | AO13: 5 | AP13: 2 | AS13: =SUM(AN13:AR13) -> 18 | AT13: 11 | AU13: 5 | AV13: 2 | AY13: =SUM(AT13:AX13) -> 18 | AZ13: 12 | BA13: 3 | BB13: 2 | BD13: 1 | BE13: =SUM(AZ13:BD13) -> 18
B14: 9 | C14: 우쿨렐레 | D14: 9 | E14: 2 | I14: =SUM(D14:H14) -> 11 | J14: 9 | K14: 2 | O14: =SUM(J14:N14) -> 11 | P14: 8 | Q14: 3 | U14: =SUM(P14:T14) -> 11 | V14: 5 | W14: 3 | X14: 2 | Y14: 1 | AA14: =SUM(V14:Z14) -> 11 | AB14: 7 | AC14: 4 | AG14: =SUM(AB14:AF14) -> 11 | AH14: 7 | AI14: 4 | AM14: =SUM(AH14:AL14) -> 11 | AN14: 6 | AO14: 5 | AS14: =SUM(AN14:AR14) -> 11 | AT14: 6 | AU14: 3 | AV14: 1 | AW14: 1 | AY14: =SUM(AT14:AX14) -> 11 | AZ14: 6 | BA14: 3 | BB14: 2 | BE14: =SUM(AZ14:BD14) -> 11
B15: 10 | C15: 댄스스포츠(중급) | D15: 17 | E15: 2 | I15: =SUM(D15:H15) -> 19 | J15: 16 | K15: 3 | O15: =SUM(J15:N15) -> 19 | P15: 16 | Q15: 3 | U15: =SUM(P15:T15) -> 19 | V15: 13 | W15: 5 | X15: 1 | AA15: =SUM(V15:Z15) -> 19 | AB15: 14 | AC15: 3 | AD15: 2 | AG15: =SUM(AB15:AF15) -> 19 | AH15: 16 | AI15: 3 | AM15: =SUM(AH15:AL15) -> 19 | AN15: 15 | AO15: 3 | AP15: 1 | AS15: =SUM(AN15:AR15) -> 19 | AT15: 15 | AU15: 4 | AY15: =SUM(AT15:AX15) -> 19 | AZ15: 16 | BA15: 3 | BE15: =SUM(AZ15:BD15) -> 19
B16: 11 | C16: 밸리댄스 | D16: 12 | E16: 2 | H16: 1 | I16: =SUM(D16:H16) -> 15 | J16: 11 | K16: 3 | N16: 1 | O16: =SUM(J16:N16) -> 15 | P16: 12 | Q16: 2 | S16: 1 | U16: =SUM(P16:T16) -> 15 | V16: 10 | W16: 3 | Z16: 2 | AA16: =SUM(V16:Z16) -> 15 | AB16: 8 | AC16: 4 | AD16: 1 | AE16: 2 | AG16: =SUM(AB16:AF16) -> 15 | AH16: 11 | AI16: 3 | AK16: 1 | AM16: =SUM(AH16:AL16) -> 15 | AN16: 9 | AO16: 4 | AQ16: 2 | AS16: =SUM(AN16:AR16) -> 15 | AT16: 8 | AU16: 6 | AX16: 1 | AY16: =SUM(AT16:AX16) -> 15 | AZ16: 7 | BA16: 7 | BD16: 1 | BE16: =SUM(AZ16:BD16) -> 15
B17: 12 | C17: 시니어건강 라인댄스 | D17: 15 | E17: 2 | F17: 1 | I17: =SUM(D17:H17) -> 18 | J17: 14 | K17: 3 | L17: 1 | O17: =SUM(J17:N17) -> 18 | P17: 14 | Q17: 4 | U17: =SUM(P17:T17) -> 18 | V17: 12 | W17: 2 | X17: 3 | Y17: 1 | AA17: =SUM(V17:Z17) -> 18 | AB17: 13 | AC17: 2 | AD17: 3 | AG17: =SUM(AB17:AF17) -> 18 | AH17: 14 | AI17: 2 | AJ17: 2 | AM17: =SUM(AH17:AL17) -> 18 | AN17: 13 | AO17: 3 | AP17: 2 | AS17: =SUM(AN17:AR17) -> 18 | AT17: 12 | AU17: 2 | AV17: 4 | AY17: =SUM(AT17:AX17) -> 18 | AZ17: 13 | BA17: 3 | BB17: 2 | BE17: =SUM(AZ17:BD17) -> 18
B18: 13 | C18: 시니어 건강체조 | D18: 3 | E18: 4 | F18: 2 | G18: 1 | I18: =SUM(D18:H18) -> 10 | J18: 2 | K18: 3 | L18: 2 | M18: 3 | O18: =SUM(J18:N18) -> 10 | P18: 2 | Q18: 4 | R18: 3 | S18: 1 | U18: =SUM(P18:T18) -> 10 | V18: 2 | W18: 4 | X18: 4 | AA18: =SUM(V18:Z18) -> 10 | AB18: 2 | AC18: 4 | AD18: 4 | AG18: =SUM(AB18:AF18) -> 10 | AH18: 2 | AI18: 4 | AJ18: 4 | AM18: =SUM(AH18:AL18) -> 10 | AN18: 2 | AO18: 4 | AP18: 1 | AQ18: 3 | AS18: =SUM(AN18:AR18) -> 10 | AT18: 2 | AU18: 4 | AV18: 4 | AY18: =SUM(AT18:AX18) -> 10 | AZ18: 2 | BA18: 4 | BB18: 4 | BE18: =SUM(AZ18:BD18) -> 10
B19: 14 | C19: 한글교실(어르신) | D19: 13 | I19: =SUM(D19:H19) -> 13 | J19: 13 | O19: =SUM(J19:N19) -> 13 | P19: 13 | U19: =SUM(P19:T19) -> 13 | V19: 11 | W19: 2 | AA19: =SUM(V19:Z19) -> 13 | AB19: 10 | AC19: 3 | AG19: =SUM(AB19:AF19) -> 13 | AH19: 12 | AI19: 1 | AM19: =SUM(AH19:AL19) -> 13 | AN19: 11 | AO19: 2 | AS19: =SUM(AN19:AR19) -> 13 | AT19: 10 | AU19: 3 | AY19: =SUM(AT19:AX19) -> 13 | AZ19: 10 | BA19: 2 | BB19: 1 | BE19: =SUM(AZ19:BD19) -> 13
B20: 15 | C20: 컴퓨터&스마트폰 기초(키오스크활용) | D20: 15 | I20: =SUM(D20:H20) -> 15 | J20: 15 | O20: =SUM(J20:N20) -> 15 | P20: 14 | Q20: 1 | U20: =SUM(P20:T20) -> 15 | V20: 13 | W20: 2 | AA20: =SUM(V20:Z20) -> 15 | AB20: 14 | AC20: 1 | AG20: =SUM(AB20:AF20) -> 15 | AH20: 15 | AM20: =SUM(AH20:AL20) -> 15 | AN20: 11 | AO20: 2 | AP20: 2 | AS20: =SUM(AN20:AR20) -> 15 | AT20: 6 | AU20: 4 | AV20: 5 | AY20: =SUM(AT20:AX20) -> 15 | AZ20: 14 | BA20: 1 | BE20: =SUM(AZ20:BD20) -> 15
B21: 16 | C21: 영어교실(어르신) | I21: =SUM(D21:H21) -> 0 | O21: =SUM(J21:N21) -> 0 | U21: =SUM(P21:T21) -> 0 | AA21: =SUM(V21:Z21) -> 0 | AG21: =SUM(AB21:AF21) -> 0 | AM21: =SUM(AH21:AL21) -> 0 | AS21: =SUM(AN21:AR21) -> 0 | AY21: =SUM(AT21:AX21) -> 0 | BE21: =SUM(AZ21:BD21) -> 0

Sheet 주관식(좋았던 점 및 개선할점)
B1: 주관식 질문
B3: 연번 | C3: 프로그램명 | D3: 교육과 관련하여 좋았던 점 이나 개선할 점
B4: 1 | C4: 컴퓨터활용능력 2급 실기 자격증(온라인) | D4: 자격증반 수업은 자격증 취득이 가능한 정도의 수업이 될 수 있을 만큼의 수업시간이 필요할 것 같습니다. 현재는 많이 부족한 듯합니다.
B5: 2 | C5: 정리수납 전문가 자격과정 | D5: 이론수업도 했으면 좋겠습니다
B6: 3 | C6: 한글&엑셀 기초실무 | D6: 교육 덕분에 컴퓨터 실제 사용 범위가 넓어져 만족스럽습니다.
B7: 4 | C7: 영어회화(초급) | D7: 자격증 과정이니 필기 수업도 함께 하면 좋겠습니다.
B8: 5 | C8: 어르신이 행복한 웃음치료 | D8: 컴활2급실기 자격증과정에서 주2시간수업은 너무 빠듯한거 같아요. 필기수업도 병행하고 강의시간을 늘렸으면 좋겠습니다.
B9: 6 | C9: 힐링 노래교실 | D9: 컴활능력 필기시험과정도 함께 배울 수 있었으면 좋겠습니다.
B10: 7 | C10: 한문서예 | D10: 실기만 했는데 필기도 했으면 더욱 좋을 뻔 했습니다
B11: 8 | C11: 치매예방 미술 프로그램(연필스케치) | D11: 철학과 종교에 관한 강좌 개설을 원합니다.
B12: 9 | C12: 우쿨렐레 | D12: 수강 내용이 충실하고 만족스럽다
B13: 10 | C13: 댄스스포츠(중급) | D13: 기본개념에 대한 설명이 좋았고 이해에 도움이 되었습니다.
B14: 11 | C14: 밸리댄스 | D14: 컴퓨터가 낡아서 간혹 힘들다
B15: 12 | C15: 시니어건강 라인댄스 | D15: 교육강사가 열정적이고 질문에 상세하고 친절하게 설명해주신다.너무고맙다
... B19: 16 | C19: 영어교실(어르신) | D19: 짧은 시간이지만 조금이라도 서로 영어로 대화할수 있어 좋다
B20: 17 | D20: 같은 방향성의 학습을 통해 사람간 친밀감을 조금이나마 느낄 수 있어서 좋습니다. 그런데 분기 마다 끊기며 지속성이 없는게 아쉽네요. 조금만 더 연속성이 있으면 좋겠다는 견해입니다.
B21: 18 | D21: 요가 시간을 오전으로 변경해 주시면 감사하겠습니다~~
B22: 19 | D22: 한학기마다 추첨하기보다 영어회화는 일년 고정되어야 선생님이 학생들의 발천을 볼수 있습니다. 참고해주세요!
B23: 20 | D23: 알차요^^
B24: 21 | D24: 추첨방식때문에 연속성이 없다 그래서 실효성이 떨어진다.
B25: 22 | D25: 원어민강사의 수업이 마우 좋습니다!
B26: 23 | D26: 유익한 배움의 시간 이였습니다
B27: 24 | D27: 모든것이 좋아요 특히 강사선생님이 자상하고 친절 하셔서 좋아요
B28: 25 | D28: 선생님 재미있게가르켜주셔서 감사합니다
B29: 26 | D29: 라인댄스읜원을늘려주세요
B30: 27 | D30: 요시간대에 진행하는 요가수업이 정말 좋습니다. 이시간의 요가수업이 계속되길 희망합니다.
B31: 28 | D31: 건강을 지켜주는 프로그램이므로 지속카능할 수 있기를 바랍니다
... B140: 137 | D140: 선생님과 동료들로부터 운동과 치료에 대한 정보를 얻을 수 있어서 도움이 되었어요

Sheet 2. 출석률 
B1: 2026년 양촌읍 가까이배움터 정규강좌 1기 출석률 및 수료율
I2: 인원 : 명
B3: 연번 | C3: 구분 | D3: 과목명 | E3: 모집정원 | F3: 수강인원 | G3: 출석률 | H3: 수료인원 | I3: 수료율
D4: 계 | E4: =SUM(E5:E20) -> 301 | F4: =SUM(F5:F20) -> 266 | G4: =AVERAGE(G5:G20) -> 0.82284686 | H4: =SUM(H5:H20) -> 217 | I4: =AVERAGE(I5:I19) -> 0.80518906
B5: 1 | C5: 직업능력 | D5: 컴퓨터활용능력 2급 실기 자격증(온라인) | E5: 16 | F5: 12 | G5: =AVERAGE('개인별 출석현황'!I4:I15) -> 0.72435897 | H5: =COUNTIF('개인별 출석현황'!J4:J15,"수료") -> 8 | I5: =H5/F5 -> 0.66666667
B6: 2 | D6: 정리수납 전문가 자격과정 | E6: 16 | F6: 6 | G6: =AVERAGE('개인별 출석현황'!I16:I21) -> 0.85714286 | H6: =COUNTIF('개인별 출석현황'!J16:J21,"수료") -> 5 | I6: =H6/F6 -> 0.83333333
B7: 3 | C7: 인문교양 | D7: 한글&엑셀 기초실무 | E7: 15 | F7: 12 | G7: =AVERAGE('개인별 출석현황'!I22:I33) -> 0.8974359 | H7: =COUNTIF('개인별 출석현황'!J22:J33,"수료") -> 11 | I7: =H7/F7 -> 0.91666667
B8: 4 | D8: 영어회화(초급) | E8: 16 | F8: 15 | G8: =AVERAGE('개인별 출석현황'!I34:I48) -> 0.77142857 | H8: =COUNTIF('개인별 출석현황'!J34:J48,"수료") -> 11 | I8: =H8/F8 -> 0.73333333
B9: 5 | D9: 어르신이 행복한 웃음치료 | E9: 16 | F9: 15 | G9: =AVERAGE('개인별 출석현황'!I49:I63) -> 0.82857143 | H9: =COUNTIF('개인별 출석현황'!J49:J63,"수료") -> 12 | I9: =H9/F9 -> 0.8
B10: 6 | C10: 문화예술 | D10: 힐링 노래교실 | E10: 40 | F10: 39 | G10: =AVERAGE('개인별 출석현황'!I64:I102) -> 0.83234714 | H10: =COUNTIF('개인별 출석현황'!J64:J102,"수료") -> 31 | I10: =H10/F10 -> 0.79487179
B11: 7 | D11: 한문서예 | E11: 16 | F11: 12 | G11: =AVERAGE('개인별 출석현황'!I103:I114) -> 0.79166667 | H11: =COUNTIF('개인별 출석현황'!J103:J114,"수료") -> 10 | I11: =H11/F11 -> 0.83333333
B12: 8 | D12: 치매예방 미술 프로그램(연필스케치) | E12: 15 | F12: 15 | G12: =AVERAGE('개인별 출석현황'!I115:I129) -> 0.66666667 | H12: =COUNTIF('개인별 출석현황'!J115:J129,"수료") -> 11 | I12: =H12/F12 -> 0.73333333
B13: 9 | D13: 우쿨렐레 | E13: 16 | F13: 16 | G13: =AVERAGE('개인별 출석현황'!I130:I145) -> 0.87053571 | H13: =COUNTIF('개인별 출석현황'!J130:J145,"수료") -> 14 | I13: =H13/F13 -> 0.875
B14: 10 | D14: 댄스스포츠(중급) | E14: 26 | F14: 25 | G14: =AVERAGE('개인별 출석현황'!I146:I170) -> 0.74428571 | H14: =COUNTIF('개인별 출석현황'!J146:J170,"수료") -> 19 | I14: =H14/F14 -> 0.76
B15: 11 | D15: 밸리댄스 | E15: 20 | F15: 18 | G15: =AVERAGE('개인별 출석현황'!I171:I188) -> 0.81150794 | H15: =COUNTIF('개인별 출석현황'!J171:J188,"수료") -> 14 | I15: =H15/F15 -> 0.77777778
B16: 12 | D16: 시니어건강 라인댄스 | E16: 24 | F16: 23 | G16: =AVERAGE('개인별 출석현황'!I189:I211) -> 0.89596273 | H16: =COUNTIF('개인별 출석현황'!J189:J211,"수료") -> 21 | I16: =H16/F16 -> 0.91304348
B17: 13 | D17: 시니어 건강체조 | E17: 20 | F17: 18 | G17: =AVERAGE('개인별 출석현황'!I212:I229) -> 0.88095238 | H17: =COUNTIF('개인별 출석현황'!J212:J229,"수료") -> 15 | I17: =H17/F17 -> 0.83333333
B18: 14 | C18: 기초문해 | D18: 한글교실(어르신) | E18: 15 | F18: 12 | G18: =AVERAGE('개인별 출석현황'!I230:I241) -> 0.80952381 | H18: =COUNTIF('개인별 출석현황'!J230:J241,"수료") -> 9 | I18: =H18/F18 -> 0.75
B19: 15 | D19: 컴퓨터&스마트폰 기초(키오스크활용) | E19: 15 | F19: 14 | G19: =AVERAGE('개인별 출석현황'!I242:I255) -> 0.81632653 | H19: =COUNTIF('개인별 출석현황'!J242:J255,"수료") -> 12 | I19: =H19/F19 -> 0.85714286
B20: 16 | D20: 영어교실(어르신) | E20: 15 | F20: 14 | G20: =AVERAGE('개인별 출석현황'!I256:I269) -> 0.96683673 | H20: =COUNTIF('개인별 출석현황'!J256:J269,"수료") -> 14 | I20: =H20/F20 -> 1

Sheet 개인별 출석현황
B1: 수강생 개인별 출석 현황
B3: 연번 | C3: 과목명 | D3: 이름 | E3: 성별 | F3: 생년월일 | G3: 수업일 | H3: 출석일 | I3: 출석률 | J3: 수료여부
B4: 1 | C4: 컴퓨터활용능력 2급 실기 자격증(온라인) | D4: 곽은정 | E4: 여성 | F4: 1982.04.26 | G4: 13 | H4: 11 | I4: =H4/G4 -> 0.84615385 | J4: =IF(I4>=70%,"수료","미수료") -> 수료
B5: 2 | D5: 김보경 | E5: 여성 | F5: 1970.01.19 | G5: 13 | H5: 1 | I5: =H5/G5 -> 0.076923077 | J5: =IF(I5>=70%,"수료","미수료") -> 미수료
B6: 3 | D6: 김시응 | E6: 남성 | F6: 1957.04.21 | G6: 13 | H6: 12 | I6: =H6/G6 -> 0.92307692 | J6: =IF(I6>=70%,"수료","미수료") -> 수료
B7: 4 | D7: 김아진 | E7: 여성 | F7: 2007.11.28 | G7: 13 | H7: 5 | I7: =H7/G7 -> 0.38461538 | J7: =IF(I7>=70%,"수료","미수료") -> 미수료
B8: 5 | D8: 문승연 | E8: 여성 | F8: 2007.01.18 | G8: 13 | H8: 11 | I8: =H8/G8 -> 0.84615385 | J8: =IF(I8>=70%,"수료","미수료") -> 수료
B9: 6 | D9: 윤선애 | E9: 여성 | F9: 1981.02.02 | G9: 13 | H9: 12 | I9: =H9/G9 -> 0.92307692 | J9: =IF(I9>=70%,"수료","미수료") -> 수료
B10: 7 | D10: 이다형 | E10: 여성 | F10: 2002.04.21 | G10: 13 | H10: 10 | I10: =H10/G10 -> 0.76923077 | J10: =IF(I10>=70%,"수료","미수료") -> 수료
B11: 8 | D11: 이진남 | E11: 남성 | F11: 1954.01.27 | G11: 13 | H11: 12 | I11: =H11/G11 -> 0.92307692 | J11: =IF(I11>=70%,"수료","미수료") -> 수료
B12: 9 | D12: 이혜원 | E12: 여성 | F12: 1986.09.23 | G12: 13 | H12: 10 | I12: =H12/G12 -> 0.76923077 | J12: =IF(I12>=70%,"수료","미수료") -> 수료
B13: 10 | D13: 정인영 | E13: 여성 | F13: 1996.01.16 | G13: 13 | H13: 8 | I13: =H13/G13 -> 0.61538462 | J13: =IF(I13>=70%,"수료","미수료") -> 미수료
B14: 11 | D14: 천현진 | E14: 여성 | F14: 1978.11.01 | G14: 13 | H14: 8 | I14: =H14/G14 -> 0.61538462 | J14: =IF(I14>=70%,"수료","미수료") -> 미수료
B15: 12 | D15: 한유진 | E15: 여성 | F15: 1973.12.01 | G15: 13 | H15: 13 | I15: =H15/G15 -> 1 | J15: =IF(I15>=70%,"수료","미수료") -> 수료
B16: 13 | C16: 정리수납 전문가 자격과정 | D16: 구미옥 | E16: 여성 | F16: 1966.10.31 | G16: 14 | H16: 6 | I16: =H16/G16 -> 0.42857143 | J16: =IF(I16>=70%,"수료","미수료") -> 미수료
B17: 14 | D17: 박은경 | E17: 여성 | F17: 1983.06.18 | G17: 14 | H17: 14 | I17: =H17/G17 -> 1 | J17: =IF(I17>=70%,"수료","미수료") -> 수료
B18: 15 | D18: 박지영 | E18: 여성 | F18: 1984.08.30 | G18: 14 | H18: 13 | I18: =H18/G18 -> 0.92857143 | J18: =IF(I18>=70%,"수료","미수료") -> 수료
B19: 16 | D19: 안순옥 | E19: 여성 | F19: 1965.03.17 | G19: 14 | H19: 13 | I19: =H19/G19 -> 0.92857143 | J19: =IF(I19>=70%,"수료","미수료") -> 수료
B20: 17 | D20: 조상민 | E20: 여성 | F20: 1984.01.14 | G20: 14 | H20: 13 | I20: =H20/G20 -> 0.92857143 | J20: =IF(I20>=70%,"수료","미수료") -> 수료
B21: 18 | D21: 한은진 | E21: 여성 | F21: 1963.01.15 | G21: 14 | H21: 13 | I21: =H21/G21 -> 0.92857143 | J21: =IF(I21>=70%,"수료","미수료") -> 수료
B22: 19 | C22: 한글&엑셀 기초실무 | D22: 곽명근 | E22: 남성 | F22: 1957.01.30 | G22: 13 | H22: 13 | I22: =H22/G22 -> 1 | J22: =IF(I22>=70%,"수료","미수료") -> 수료
B23: 20 | D23: 김상욱 | E23: 남성 | F23: 1958.02.28 | G23: 13 | H23: 11 | I23: =H23/G23 -> 0.84615385 | J23: =IF(I23>=70%,"수료","미수료") -> 수료
B24: 21 | D24: 김영원 | E24: 남성 | F24: 1957.02.22 | G24: 13 | H24: 13 | I24: =H24/G24 -> 1 | J24: =IF(I24>=70%,"수료","미수료") -> 수료
B25: 22 | D25: 김지숙 | E25: 여성 | F25: 1970.09.24 | G25: 13 | H25: 12 | I25: =H25/G25 -> 0.92307692 | J25: =IF(I25>=70%,"수료","미수료") -> 수료
B26: 23 | D26: 배민선 | E26: 여성 | F26: 1979.09.10 | G26: 13 | H26: 11 | I26: =H26/G26 -> 0.84615385 | J26: =IF(I26>=70%,"수료","미수료") -> 수료
B27: 24 | D27: 백선옥 | E27: 여성 | F27: 1956.06.10 | G27: 13 | H27: 12 | I27: =H27/G27 -> 0.92307692 | J27: =IF(I27>=70%,"수료","미수료") -> 수료
B28: 25 | D28: 안금자 | E28: 여성 | F28: 1952.06.26 | G28: 13 | H28: 13 | I28: =H28/G28 -> 1 | J28: =IF(I28>=70%,"수료","미수료") -> 수료
B29: 26 | D29: 오진아 | E29: 여성 | F29: 1991.12.11 | G29: 13 | H29: 8 | I29: =H29/G29 -> 0.61538462 | J29: =IF(I29>=70%,"수료","미수료") -> 미수료
B30: 27 | D30: 유영애 | E30: 여성 | F30: 1979.01.25 | G30: 13 | H30: 12 | I30: =H30/G30 -> 0.92307692 | J30: =IF(I30>=70%,"수료","미수료") -> 수료
B31: 28 | D31: 이정매 | E31: 여성 | F31: 19701101 | G31: 13 | H31: 12 | I31: =H31/G31 -> 0.92307692 | J31: =IF(I31>=70%,"수료","미수료") -> 수료
B32: 29 | D32: 조창수 | E32: 남성 | F32: 1947.10.01 | G32: 13 | H32: 11 | I32: =H32/G32 -> 0.84615385 | J32: =IF(I32>=70%,"수료","미수료") -> 수료
B33: 30 | D33: 최성이 | E33: 여성 | F33: 1961.01.23 | G33: 13 | H33: 12 | I33: =H33/G33 -> 0.92307692 | J33: =IF(I33>=70%,"수료","미수료") -> 수료
B34: 31 | C34: 영어회화(초급) | D34: PIAO ZHONGLAN | E34: 여성 | F34: 1953.08.01 | G34: 14 | H34: 12 | I34: =H34/G34 -> 0.85714286 | J34: =IF(I34>=70%,"수료","미수료") -> 수료
B35: 32 | D35: 김미란 | E35: 여성 | F35: 1969.06.05 | G35: 14 | H35: 13 | I35: =H35/G35 -> 0.92857143 | J35: =IF(I35>=70%,"수료","미수료") -> 수료
B36: 33 | D36: 김세연 | E36: 남성 | F36: 1974.07.23 | G36: 14 | H36: 4 | I36: =H36/G36 -> 0.28571429 | J36: =IF(I36>=70%,"수료","미수료") -> 미수료
B37: 34 | D37: 김영철 | E37: 남성 | F37: 1954.05.28 | G37: 14 | H37: 13 | I37: =H37/G37 -> 0.92857143 | J37: =IF(I37>=70%,"수료","미수료") -> 수료
B38: 35 | D38: 김옥윤 | E38: 여성 | F38: 1948.01.14 | G38: 14 | H38: 12 | I38: =H38/G38 -> 0.85714286 | J38: =IF(I38>=70%,"수료","미수료") -> 수료
B39: 36 | D39: 김종협 | E39: 남성 | F39: 1950.06.20 | G39: 14 | H39: 12 | I39: =H39/G39 -> 0.85714286 | J39: =IF(I39>=70%,"수료","미수료") -> 수료
B40: 37 | D40: 김현선 | E40: 여성 | F40: 1982.01.15 | G40: 14 | H40: 11 | I40: =H40/G40 -> 0.78571429 | J40: =IF(I40>=70%,"수료","미수료") -> 수료
B41: 38 | D41: 김현숙 | E41: 여성 | F41: 1950.03.20 | G41: 14 | H41: 14 | I41: =H41/G41 -> 1 | J41: =IF(I41>=70%,"수료","미수료") -> 수료
...

Sheet 3. 원본데이터
B1: 2026년 양촌읍 가까이배움터 정규강좌 1기 만족도 조사 원본데이터
F3: P1 B2 | G3: P1 B3 | H3: P1 B4 | I3: P1 B5 | J3: P1B7 | AB3: P1B8
B4: 응답자ID | D4: 시작일시 | E4: 종료일시 | F4: 1-1 성별을 선택해 주세요. | G4: 1-2 거주지역을 선택해 주세요. | H4: 1-3 연령을 선택해 주세요. | I4: 1-4 직업을 선택해주세요. | J4: 다음 문항을 읽으시고 해당 항목에 ✔표시해 주십시오.
B5: 연번 | C5: 과목명 | F5: 응답 | G5: 응답 | H5: 응답 | I5: 응답 | J5: P1 B7.1 2-1 수강한 수업의 강사가 적극적으로 수업을 진행한다. - 응답 | L5: P1 B7.2 2-2 수강한 수업의 강사가 전문적인 지식을 갖고 진행한다. - 응답 | N5: P1 B7.3 2-3 수강한 수업의 내용과 과정이 충실히 진행되었다. - 응답 | P5: P1 B7.4 2-4 수강한 수업의 운영시간대가 적정하다고 생각한다. - 응답 | R5: P1 B7.5 2-5 수강한 수업으로 인하여 관련분야 활용에 도움이 된다. - 응답 | T5: P1 B7.6 2-6 수강한 수업이 유익하다고 생각한다. - 응답 | V5: P1 B7.7 2-7 교육교재와 보조자료는 학습에 도움이 되었다. - 응답 | X5: P1 B7.8 2-8 강의시섦 치 교육지원 매체(빔 프로젝트 등)에 대하여 만족한다.- 응답 | Z5: P1 B7.9 2-9 가까이배움터(평생학습센터)교육 프로그램에 대해 전반적으로 만족하십니까? - 응답 | AB5: 3.읍면동 가까이배움터 교육과 관련하여 좋았던 점이 있다면 어떤 의견이라도 좋으니 자유롭게 말씀해 주십시오
B6: 1 | C6: 컴퓨터활용능력 2급 실기 자격증(온라인) | D6: 2026-04-20 13:10:45 | E6: 2026-04-20 13:14:41 | F6: 여 | G6: 고촌읍 | H6: 20대 | I6: 기타 | J6: 그렇다 | K6: 4 | L6: 보통 | M6: 3 | N6: 보통 | O6: 3 | P6: 그렇다 | Q6: 4 | R6: 보통 | S6: 3 | T6: 그렇다 | U6: 4 | V6: 매우그렇다 | W6: 5 | X6: 그렇다 | Y6: 4 | Z6: 보통 | AA6: 3 | AB6: 가끔 가다 틀린 걸 알려주시거나 모르는 걸 알려주심. 그리고 진도가 너무 느림.
B7: 2 | D7: 2026-04-20 13:32:08 | E7: 2026-04-20 13:32:42 | F7: 여 | G7: 통진읍 | H7: 40대 | I7: 주부 | J7: 그렇다 | K7: 4 | L7: 그렇다 | M7: 4 | N7: 그렇다 | O7: 4 | P7: 그렇다 | Q7: 4 | R7: 그렇다 | S7: 4 | T7: 그렇다 | U7: 4 | V7: 그렇다 | W7: 4 | X7: 그렇다 | Y7: 4 | Z7: 그렇다 | AA7: 4
B8: 3 | D8: 2026-04-27 11:02:46 | E8: 2026-04-27 11:03:22 | F8: 여 | G8: 고촌읍 | H8: 40대 | I8: 직장인 | J8: 매우그렇다 | K8: 5 | L8: 매우그렇다 | M8: 5 | N8: 매우그렇다 | O8: 5 | P8: 매우그렇다 | Q8: 5 | R8: 매우그렇다 | S8: 5 | T8: 매우그렇다 | U8: 5 | V8: 매우그렇다 | W8: 5 | X8: 매우그렇다 | Y8: 5 | Z8: 매우그렇다 | AA8: 5
B9: 4 | D9: 2026-05-07 10:58:56 | E9: 2026-05-07 11:07:51 | F9: 여 | G9: 대곶면 | H9: 50대 | I9: 직장인 | J9: 매우그렇다 | K9: 5 | L9: 매우그렇다 | M9: 5 | N9: 매우그렇다 | O9: 5 | P9: 매우그렇다 | Q9: 5 | R9: 매우그렇다 | S9: 5 | T9: 매우그렇다 | U9: 5 | V9: 매우그렇다 | W9: 5 | X9: 매우그렇다 | Y9: 5 | Z9: 매우그렇다 | AA9: 5
B10: 5 | D10: 2026-05-07 11:11:32 | E10: 2026-05-07 11:12:09 | F10: 여 | G10: 장기동 | H10: 40대 | I10: 직장인 | J10: 매우그렇다 | K10: 5 | L10: 매우그렇다 | M10: 5 | N10: 매우그렇다 | O10: 5 | P10: 매우그렇다 | Q10: 5 | R10: 매우그렇다 | S10: 5 | T10: 매우그렇다 | U10: 5 | V10: 매우그렇다 | W10: 5 | X10: 매우그렇다 | Y10: 5 | Z10: 매우그렇다 | AA10: 5 | AB10: 온라인 수업 좋아요
B11: 6 | C11: 정리수납 전문가 자격과정 | D11: 2026-04-20 13:11:07 | E11: 2026-04-20 13:14:20 | F11: 여 | G11: 통진읍 | H11: 40대 | I11: 주부 | J11: 매우그렇다 | K11: 5 | L11: 매우그렇다 | M11: 5 | N11: 매우그렇다 | O11: 5 | P11: 매우그렇다 | Q11: 5 | R11: 매우그렇다 | S11: 5 | T11: 매우그렇다 | U11: 5 | V11: 매우그렇다 | W11: 5 | X11: 매우그렇다 | Y11: 5 | Z11: 매우그렇다 | AA11: 5 | AB11: 실생활에 너무 많은 도움이 되었고 1급 과정도 개설하였으면 좋겠어요~^^
B12: 7 | D12: 2026-04-20 13:14:38 | E12: 2026-04-20 13:16:13 | F12: 여 | G12: 양촌읍 | H12: 60대 | I12: 주부 | J12: 매우그렇다 | K12: 5 | L12: 매우그렇다 | M12: 5 | N12: 매우그렇다 | O12: 5 | P12: 매우그렇다 | Q12: 5 | R12: 그렇다 | S12: 4 | T12: 매우그렇다 | U12: 5 | V12: 그렇다 | W12: 4 | X12: 그렇다 | Y12: 4 | Z12: 그렇다 | AA12: 4
B13: 8 | D13: 2026-04-20 17:57:49 | E13: 2026-04-20 18:00:43 | F13: 여 | G13: 통진읍 | H13: 60대 | I13: 주부 | J13: 매우그렇다 | K13: 5 | L13: 매우그렇다 | M13: 5 | N13: 매우그렇다 | O13: 5 | P13: 매우그렇다 | Q13: 5 | R13: 매우그렇다 | S13: 5 | T13: 매우그렇다 | U13: 5 | V13: 매우그렇다 | W13: 5 | X13: 매우그렇다 | Y13: 5 | Z13: 매우그렇다 | AA13: 5 | AB13: 사회생활이나 가정생활에 필요한 도움이 되서 좋고 편리해져서 좋습니다.
B14: 9 | D14: 2026-05-07 11:00:19 | E14: 2026-05-07 11:01:04 | F14: 여 | G14: 양촌읍 | H14: 40대 | I14: 주부 | J14: 매우그렇다 | K14: 5 | L14: 매우그렇다 | M14: 5 | N14: 매우그렇다 | O14: 5 | P14: 매우그렇다 | Q14: 5 | R14: 매우그렇다 | S14: 5 | T14: 매우그렇다 | U14: 5 | V14: 매우그렇다 | W14: 5 | X14: 매우그렇다 | Y14: 5 | Z14: 매우그렇다 | AA14: 5 | AB14: 없습니다
B15: 10 | D15: 2026-05-14 09:38:18 | E15: 2026-05-14 09:39:12 | F15: 여 | G15: 양촌읍 | H15: 40대 | I15: 자영업 | J15: 매우그렇다 | K15: 5 | L15: 매우그렇다 | M15: 5 | N15: 매우그렇다 | O15: 5 | P15: 매우그렇다 | Q15: 5 | R15: 매우그렇다 | S15: 5 | T15: 매우그렇다 | U15: 5 | V15: 매우그렇다 | W15: 5 | X15: 매우그렇다 | Y15: 5 | Z15: 매우그렇다 | AA15: 5 | AB15: 강사님께서 꼼꼼하고 세심하게 잘 지도해주셔서 덕분이 잘 들었습니다.
B16: 11 | D16: 2026-05-14 09:43:59 | E16: 2026-05-14 09:46:56 | F16: 여 | G16: 통진읍 | H16: 60대 | I16: 주부 | J16: 매우그렇다 | K16: 5 | L16: 그렇다 | M16: 4 | N16: 매우그렇다 | O16: 5 | P16: 매우그렇다 | Q16: 5 | R16: 매우그렇다 | S16: 5 | T16: 매우그렇다 | U16: 5 | V16: 그렇다 | W16: 4 | X16: 매우그렇다 | Y16: 5 | Z16: 매우그렇다 | AA16: 5 | AB16: 종류가 다앙하게 좀 더 많았으면 좋겠습니다.
B17: 12 | C17: 한글&엑셀 기초실무 | D17: 2026-04-20 13:12:16 | E17: 2026-04-20 13:13:29 | F17: 여 | G17: 장기동 | H17: 50대 | I17: 주부 | J17: 매우그렇다 | K17: 5 | L17: 매우그렇다 | M17: 5 | N17: 매우그렇다 | O17: 5 | P17: 그렇다 | Q17: 4 | R17: 그렇다 | S17: 4 | T17: 매우그렇다 | U17: 5 | V17: 매우그렇다 | W17: 5 | X17: 그렇다 | Y17: 4 | Z17: 그렇다 | AA17: 4
B18: 13 | D18: 2026-04-20 13:12:28 | E18: 2026-04-20 13:13:53 | F18: 남 | G18: 양촌읍 | H18: 60대 | I18: 자영업 | J18: 매우그렇다 | K18: 5 | L18: 매우그렇다 | M18: 5 | N18: 매우그렇다 | O18: 5 | P18: 매우그렇다 | Q18: 5 | R18: 매우그렇다 | S18: 5 | T18: 매우그렇다 | U18: 5 | V18: 매우그렇다 | W18: 5 | X18: 매우그렇다 | Y18: 5 | Z18: 매우그렇다 | AA18: 5
B19: 14 | D19: 2026-04-20 13:16:07 | E19: 2026-04-20 13:19:11 | F19: 여 | G19: 양촌읍 | H19: 30대 | I19: 직장인 | J19: 매우그렇다 | K19: 5 | L19: 매우그렇다 | M19: 5 | N19: 매우그렇다 | O19: 5 | P19: 그렇다 | Q19: 4 | R19: 매우그렇다 | S19: 5 | T19: 매우그렇다 | U19: 5 | V19: 매우그렇다 | W19: 5 | X19: 매우그렇다 | Y19: 5 | Z19: 매우그렇다 | AA19: 5 | AB19: 만들기 수업도 생겼음 합니다 대부분 오전 시간이 많은데 엑셀처럼 1시수업도 좀 생겼으면함
B20: 15 | D20: 2026-04-20 15:54:12 | E20: 2026-04-20 15:56:21 | F20: 여 | G20: 하성면 | H20: 만 70대 이상 | I20: 자영업 | J20: 매우그렇다 | K20: 5 | L20: 매우그렇다 | M20: 5 | N20: 매우그렇다 | O20: 5 | P20: 그렇다 | Q20: 4 | R20: 그렇다 | S20: 4 | T20: 그렇다 | U20: 4 | V20: 그렇다 | W20: 4 | X20: 매우그렇다 | Y20: 5 | Z20: 매우그렇다 | AA20: 5
B21: 16 | D21: 2026-04-20 23:03:28 | E21: 2026-04-20 23:09:04 | F21: 남 | G21: 양촌읍 | H21: 60대 | I21: 농업,어업,축산업,임업 | J21: 그렇다 | K21: 4 | L21: 그렇다 | M21: 4 | N21: 그렇다 | O21: 4 | P21: 그렇다 | Q21: 4 | R21: 그렇다 | S21: 4 | T21: 그렇다 | U21: 4 | V21: 그렇다 | W21: 4 | X21: 보통 | Y21: 3 | Z21: 그렇다 | AA21: 4 | AB21: 빔프로젝터 선명도가 더 밝으면 합니다
B22: 17 | D22: 2026-04-21 09:11:40 | E22: 2026-04-21 09:15:56 | F22: 여 | G22: 마산동 | H22: 60대 | I22: 주부 | J22: 매우그렇다 | K22: 5 | L22: 매우그렇다 | M22: 5 | N22: 매우그렇다 | O22: 5 | P22: 매우그렇다 | Q22: 5 | R22: 그렇다 | S22: 4 | T22: 그렇다 | U22: 4 | V22: 매우그렇다 | W22: 5 | X22: 그렇다 | Y22: 4 | Z22: 그렇다 | AA22: 4 | AB22: 교재 대신 강사님이 프린트해서 나눠 줘서 감사하고 좋아요.
B23: 18 | D23: 2026-04-22 10:06:25 | E23: 2026-04-22 10:08:19 | F23: 여 | G23: 운양동 | H23: 50대 | I23: 주부 | J23: 매우그렇다 | K23: 5 | L23: 매우그렇다 | M23: 5 | N23: 매우그렇다 | O23: 5 | P23: 매우그렇다 | Q23: 5 | R23: 매우그렇다 | S23: 5 | T23: 매우그렇다 | U23: 5 | V23: 매우그렇다 | W23: 5 | X23: 매우그렇다 | Y23: 5 | Z23: 매우그렇다 | AA23: 5
B24: 19 | D24: 2026-04-27 10:54:06 | E24: 2026-04-27 10:55:16 | F24: 여 | G24: 구래동 | H24: 40대 | I24: 주부 | J24: 매우그렇다 | K24: 5 | L24: 매우그렇다 | M24: 5 | N24: 매우그렇다 | O24: 5 | P24: 그렇다 | Q24: 4 | R24: 매우그렇다 | S24: 5 | T24: 매우그렇다 | U24: 5 | V24: 매우그렇다 | W24: 5 | X24: 그렇다 | Y24: 4 | Z24: 매우그렇다 | AA24: 5
B25: 20 | D25: 2026-04-27 18:23:07 | E25: 2026-04-27 18:24:13 | F25: 여 | G25: 양촌읍 | H25: 40대 | I25: 주부 | J25: 매우그렇다 | K25: 5 | L25: 매우그렇다 | M25: 5 | N25: 매우그렇다 | O25: 5 | P25: 매우그렇다 | Q25: 5 | R25: 매우그렇다 | S25: 5 | T25: 매우그렇다 | U25: 5 | V25: 매우그렇다 | W25: 5 | X25: 그렇다 | Y25: 4 | Z25: 매우그렇다 | AA25: 5
B26: 21 | D26: 2026-04-28 04:23:34 | E26: 2026-04-28 04:27:08 | F26: 남 | G26: 양촌읍 | H26: 만 70대 이상 | I26: 기타 | J26: 매우그렇다 | K26: 5 | L26: 매우그렇다 | M26: 5 | N26: 매우그렇다 | O26: 5 | P26: 그렇다 | Q26: 4 | R26: 그렇다 | S26: 4 | T26: 그렇다 | U26: 4 | V26: 그렇다 | W26: 4 | X26: 그렇다 | Y26: 4 | Z26: 그렇다 | AA26: 4 | AB26: 컴퓨터 기기 업그레이드가 필요하다.
B27: 22 | D27: 2026-05-04 13:30:19 | E27: 2026-05-04 13:44:34 | F27: 여 | G27: 양촌읍 | H27: 만 70대 이상 | I27: 기타 | J27: 매우그렇다 | K27: 5 | L27: 매우그렇다 | M27: 5 | N27: 매우그렇다 | O27: 5 | P27: 매우그렇다 | Q27: 5 | R27: 매우그렇다 | S27: 5 | T27: 매우그렇다 | U27: 5 | V27: 매우그렇다 | W27: 5 | X27: 매우그렇다 | Y27: 5 | Z27: 매우그렇다 | AA27: 5 | AB27: 필요한 한글이나 엑셀에 관하여 많은 도움이 되었다
B28: 23 | D28: 2026-05-07 11:43:50 | E28: 2026-05-07 11:45:40 | F28: 남 | G28: 고촌읍 | H28: 60대 | I28: 기타 | J28: 그렇다 | K28: 4 | L28: 그렇다 | M28: 4 | N28: 그렇다 | O28: 4 | P28: 그렇다 | Q28: 4 | R28: 그렇다 | S28: 4 | T28: 그렇다 | U28: 4 | V28: 보통 | W28: 3 | X28: 그렇다 | Y28: 4 | Z28: 그렇다 | AA28: 4 | AB28: 강사님의 충실한 강의에 감사드립니다
B29: 24 | C29: 영어회화(초급) | D29: 2026-04-20 13:14:54 | E29: 2026-04-20 13:25:06 | F29: 여 | G29: 양촌읍 | H29: 만 70대 이상 | I29: 주부 | J29: 매우그렇다 | K29: 5 | L29: 매우그렇다 | M29: 5 | N29: 매우그렇다 | O29: 5 | P29: 매우그렇다 | Q29: 5 | R29: 보통 | S29: 3 | T29: 매우그렇다 | U29: 5 | V29: 매우그렇다 | W29: 5 | X29: 매우그렇다 | Y29: 5 | Z29: 매우그렇다 | AA29: 5
B30: 25 | D30: 2026-04-20 13:36:52 | E30: 2026-04-20 13:39:32 | F30: 남 | G30: 양촌읍 | H30: 만 70대 이상 | I30: 기타 | J30: 그렇다 | K30: 4 | L30: 그렇다 | M30: 4 | N30: 그렇다 | O30: 4 | P30: 그렇다 | Q30: 4 | R30: 그렇다 | S30: 4 | T30: 그렇다 | U30: 4 | V30: 그렇다 | W30: 4 | X30: 그렇다 | Y30: 4 | Z30: 그렇다 | AA30: 4 | AB30: 교재 및 준비성을 성의껏 잘 해오십니다 열심히 노력하시는 선생님 입니다.
B31: 26 | D31: 2026-04-20 13:40:13 | E31: 2026-04-20 13:42:58 | F31: 여 | G31: 구래동 | H31: 60대 | I31: 주부 | J31: 매우그렇다 | K31: 5 | L31: 그렇다 | M31: 4 | N31: 매우그렇다 | O31: 5 | P31: 매우그렇다 | Q31: 5 | R31: 매우그렇다 | S31: 5 | T31: 매우그렇다 | U31: 5 | V31: 매우그렇다 | W31: 5 | X31: 매우그렇다 | Y31: 5 | Z31: 매우그렇다 | AA31: 5 | AB31: 강사님이 적극적이고 충실히 강의를 해주셔서 큰도움을 받고 있는데 계속지속되었으면
B32: 27 | D32: 2026-04-20 13:40:57 | E32: 2026-04-20 13:47:39 | F32: 여 | G32: 양촌읍 | H32: 만 70대 이상 | I32: 주부 | J32: 매우그렇다 | K32: 5 | L32: 매우그렇다 | M32: 5 | N32: 매우그렇다 | O32: 5 | P32: 매우그렇다 | Q32: 5 | R32: 그렇다 | S32: 4 | T32: 그렇다 | U32: 4 | V32: 그렇다 | W32: 4 | X32: 그렇다 | Y32: 4 | Z32: 그렇다 | AA32: 4 | AB32: 영어 공부를 통해 지적 향상이 되어서 매우좋다
B33: 28 | D33: 2026-04-20 13:57:06 | E33: 2026-04-20 13:58:56 | F33: 여 | G33: 양촌읍 | H33: 50대 | I33: 주부 | J33: 매우그렇다 | K33: 5 | L33: 매우그렇다 | M33: 5 | N33: 매우그렇다 | O33: 5 | P33: 매우그렇다 | Q33: 5 | R33: 매우그렇다 | S33: 5 | T33: 매우그렇다 | U33: 5 | V33: 매우그렇다 | W33: 5 | X33: 매우그렇다 | Y33: 5 | Z33: 매우그렇다 | AA33: 5 | AB33: 오카리나 수업이 생겼으면 좋겠습니다
B34: 29 | D34: 2026-04-24 17:20:43 | E34: 2026-04-24 17:24:56 | F34: 여 | G34: 양촌읍 | H34: 만 70대 이상 | I34: 주부 | J34: 매우그렇다 | K34: 5 | L34: 매우그렇다 | M34: 5 | N34: 매우그렇다 | O34: 5 | P34: 그렇다 | Q34: 4 | R34: 매우그렇다 | S34: 5 | T34: 매우그렇다 | U34: 5 | V34: 매우그렇다 | W34: 5 | X34: 매우그렇다 | Y34: 5 | Z34: 매우그렇다 | AA34: 5 | AB34: 강사님이 열정이 넘치고 적극적으로 강의하십니다.
B35: 30 | D35: 2026-04-27 10:57:17 | E35: 2026-04-27 10:58:24 | F35: 여 | G35: 양촌읍 | H35: 40대 | I35: 직장인 | J35: 매우그렇다 | K35: 5 | L35: 매우그렇다 | M35: 5 | N35: 매우그렇다 | O35: 5 | P35: 매우그렇다 | Q35: 5 | R35: 매우그렇다 | S35: 5 | T35: 매우그렇다 | U35: 5 | V35: 매우그렇다 | W35: 5 | X35: 매우그렇다 | Y35: 5 | Z35: 매우그렇다 | AA35: 5 | AB35: 지금처럼 유익한교육 지속적으로 유지해주세요
B36: 31 | D36: 2026-04-27 10:56:54 | E36: 2026-04-27 11:00:43 | F36: 여 | G36: 구래동 | H36: 만 70대 이상 | I36: 주부 | J36: 그렇다 | K36: 4 | L36: 그렇다 | M36: 4 | N36: 그렇다 | O36: 4 | P36: 그렇다 | Q36: 4 | R36: 보통 | S36: 3 | T36: 그렇다 | U36: 4 | V36: 그렇다 | W36: 4 | X36: 그렇다 | Y36: 4 | Z36: 매우그렇다 | AA36: 5 | AB36: 공부하는 재미가 있고 배움에 행복함이 있습니다.
B37: 32 | D37: 2026-04-27 11:40:44 | E37: 2026-04-27 11:46:05 | F37: 남 | G37: 양촌읍 | H37: 만 70대 이상 | I37: 기타 | J37: 매우그렇다 | K37: 5 | L37: 매우그렇다 | M37: 5 | N37: 매우그렇다 | O37: 5 | P37: 매우그렇다 | Q37: 5 | R37: 매우그렇다 | S37: 5 | T37: 그렇다 | U37: 4 | V37: 그렇다 | W37: 4 | X37: 그렇다 | Y37: 4 | Z37: 그렇다 | AA37: 4 | AB37: 항상 알기쉽게 가르치시는 선생님게 감사 하며 가정이 평안하시길 기원 함니다
B38: 33 | D38: 2026-04-27 11:59:39 | E38: 2026-04-27 12:00:33 | F38: 여 | G38: 양촌읍 | H38: 만 70대 이상 | I38: 주부 | J38: 매우그렇다 | K38: 5 | L38: 매우그렇다 | M38: 5 | N38: 매우그렇다 | O38: 5 | P38: 매우그렇다 | Q38: 5 | R38: 매우그렇다 | S38: 5 | T38: 매우그렇다 | U38: 5 | V38: 매우그렇다 | W38: 5 | X38: 매우그렇다 | Y38: 5 | Z38: 매우그렇다 | AA38: 5
B39: 34 | D39: 2026-04-27 18:19:54 | E39: 2026-04-27 18:21:00 | F39: 여 | G39: 양촌읍 | H39: 만 70대 이상 | I39: 주부 | J39: 그렇다 | K39: 4 | L39: 그렇다 | M39: 4 | N39: 그렇다 | O39: 4 | P39: 매우그렇다 | Q39: 5 | R39: 그렇다 | S39: 4 | T39: 그렇다 | U39: 4 | V39: 그렇다 | W39: 4 | X39: 그렇다 | Y39: 4 | Z39: 그렇다 | AA39: 4
B40: 35 | D40: 2026-05-06 10:50:35 | E40: 2026-05-06 10:52:09 | F40: 여 | G40: 양촌읍 | H40: 40대 | I40: 주부 | J40: 매우그렇다 | K40: 5 | L40: 매우그렇다 | M40: 5 | N40: 매우그렇다 | O40: 5 | P40: 매우그렇다 | Q40: 5 | R40: 매우그렇다 | S40: 5 | T40: 매우그렇다 | U40: 5 | V40: 매우그렇다 | W40: 5 | X40: 매우그렇다 | Y40: 5 | Z40: 매우그렇다 | AA40: 5 | AB40: 조정외 선생님 처음 만나뵈엇는데 정말 실력이 늘어나는 느낌 수업 받는동안 너무 행복합니다
B41: 36 | D41: 2026-05-06 10:52:04 | E41: 2026-05-06 10:52:58 | F41: 남 | G41: 마산동 | H41: 만 70대 이상 | I41: 기타 | J41: 매우그렇다 | K41: 5 | L41: 매우그렇다 | M41: 5 | N41: 매우그렇다 | O41: 5 | P41: 매우그렇다 | Q41: 5 | R41: 매우그렇다 | S41: 5 | T41: 매우그렇다 | U41: 5 | V41: 그렇다 | W41: 4 | X41: 그렇다 | Y41: 4 | Z41: 그렇다 | AA41: 4 | AB41: 강사좋아요
...
